<?xml version='1.0' encoding='utf-8'?>
<robot name="basket">

    <link name="link0">
      <inertial>
        <origin xyz="0 0 0" rpy="0 0 0" />
        <mass value="0.001" />
        <inertia ixx="0.01" iyy="0.01" izz="0.01" ixy="0" ixz="0" iyz="0" />
      </inertial>
    </link>
    <link name="link1">
      <inertial>
        <origin xyz="0 0 0" rpy="0 0 0" />
        <mass value="1e-10" />
        <inertia ixx="1e-10" iyy="1e-10" izz="1e-10" ixy="0" ixz="0" iyz="0" />
      </inertial>
    </link>
    <link name="link2">
      <inertial>
        <origin xyz="0 0 0" rpy="0 0 0" />
        <mass value="1e-10" />
        <inertia ixx="1e-10" iyy="1e-10" izz="1e-10" ixy="0" ixz="0" iyz="0" />
      </inertial>
    </link>
    <link name="link3">
      <inertial>
        <origin xyz="0 0 0" rpy="0 0 0" />
        <mass value="1e-10" />
        <inertia ixx="1e-10" iyy="1e-10" izz="1e-10" ixy="0" ixz="0" iyz="0" />
      </inertial>
    </link>
      <link name="link4">
      <inertial>
        <origin xyz="0 0 0" rpy="0 0 0" />
        <mass value="1e-10" />
        <inertia ixx="1e-10" iyy="1e-10" izz="1e-10" ixy="0" ixz="0" iyz="0" />
      </inertial>
    </link>
    <link name="link5">
      <inertial>
        <origin xyz="0 0 0" rpy="0 0 0" />
        <mass value="1e-10" />
        <inertia ixx="1e-10" iyy="1e-10" izz="1e-10" ixy="0" ixz="0" iyz="0" />
      </inertial>
    </link>

  <!--BASKET LINKS-->
    <link name="basket_wall1">
      <inertial>
        <origin xyz="0 0 0" rpy="0 0 0" />
        <mass value="0.1" />
        <inertia ixx="1e-2" iyy="1e-2" izz="1e-2" ixy="0" ixz="0" iyz="0" />
      </inertial>
      <visual>
        <origin xyz="0.0 0.0 0" rpy="0 0 0" />
        <geometry>
          <box size="0.005 0.5 0.25" />
        </geometry>
        <material name="material">
              <color rgba="0.956 0.815 0.24 1.0" />
        </material>
    </visual>
      <collision>
       <origin xyz="0.0 0.0 0" rpy="0 0 0" />
        <geometry>
          <box size="0.005 0.5 0.25" />
        </geometry>
      </collision>
    </link>
    <link name="basket_wall2">
      <inertial>
        <origin xyz="0 0 0" rpy="0 0 0" />
        <mass value="0.1" />
        <inertia ixx="1e-2" iyy="1e-2" izz="1e-2" ixy="0" ixz="0" iyz="0" />
      </inertial>
      <visual>
        <origin xyz="0.3 0.0 0" rpy="0 0 0" />
        <geometry>
          <box size="0.005 0.5 0.25" />
        </geometry>
        <material name="material">
              <color rgba="0.956 0.815 0.24 1.0" />
        </material>
    </visual>
      <collision>
        <origin xyz="0.3 0.0 0" rpy="0 0 0" />
        <geometry>
          <box size="0.005 0.5 0.25" />
        </geometry>
      </collision>
    </link>
    <link name="basket_wall3">
      <inertial>
        <origin xyz="0 0 0" rpy="0 0 0" />
        <mass value="0.1" />
        <inertia ixx="1e-2" iyy="1e-2" izz="1e-2" ixy="0" ixz="0" iyz="0" />
      </inertial>
      <visual>
         <origin xyz="0.15 0.25 0" rpy="0 0 0" />
      <geometry>
        <box size="0.29 0.005 0.24" />
      </geometry>
        <material name="material">
              <color rgba="0.956 0.815 0.24 1.0" />
        </material>
    </visual>
      <collision>
         <origin xyz="0.15 0.25 0" rpy="0 0 0" />
      <geometry>
        <box size="0.29 0.005 0.24" />
      </geometry>
      </collision>
    </link>
    <link name="basket_wall4">
      <inertial>
        <origin xyz="0 0 0" rpy="0 0 0" />
        <mass value="0.1" />
        <inertia ixx="1e-2" iyy="1e-2" izz="1e-2" ixy="0" ixz="0" iyz="0" />
      </inertial>
      <visual>
         <origin xyz="0.15 -0.25 0" rpy="0 0 0" />
      <geometry>
        <box size="0.29 0.005 0.24" />
      </geometry>
        <material name="material">
              <color rgba="0.956 0.815 0.24 1.0" />
        </material>
    </visual>
      <collision>
         <origin xyz="0.15 -0.25 0" rpy="0 0 0" />
      <geometry>
        <box size="0.29 0.005 0.24" />
      </geometry>
      </collision>
    </link>
    <link name="basket_wall5">
      <inertial>
        <origin xyz="0 0 0" rpy="0 0 0" />
        <mass value="0.1" />
        <inertia ixx="1e-2" iyy="1e-2" izz="1e-2" ixy="0" ixz="0" iyz="0" />
      </inertial>
      <visual>
         <origin xyz="0.15 0.0 -0.125" rpy="0 0 0" />
      <geometry>
        <box size="0.3 0.5 0.005" />
      </geometry>
        <material name="material">
              <color rgba="0.956 0.815 0.24 1.0" />
        </material>
    </visual>
    </link>



    <!--JOINTS DOF-->
    <joint name="joint1" type="prismatic">
      <origin xyz="0 0 0" rpy="0 0 0"/>
      <parent link="link0"/>
      <child link="link1"/>
      <axis xyz="0 0 1"/>
      <limit effort="21.3" lower="-100" upper="100" velocity="21.3"/>
    </joint>
    <joint name="joint2" type="prismatic">
      <origin xyz="0 0 0" rpy="0 0 0"/>
      <parent link="link1"/>
      <child link="link2"/>
      <axis xyz="0 1 0"/>
      <limit effort="21.3" lower="-100" upper="100" velocity="21.3"/>
    </joint>
    <joint name="joint3" type="prismatic">
      <origin xyz="0 0 0" rpy="0 0 0"/>
      <parent link="link2"/>
      <child link="link3"/>
      <axis xyz="1 0 0"/>
      <limit effort="21.3" lower="-100" upper="100" velocity="21.3"/>
    </joint>
    <joint name="joint4" type="revolute">
      <origin xyz="0 0 0" rpy="0 0 0"/>
      <parent link="link3"/>
      <child link="link4"/>
        <axis xyz="1 0 0"/>
      <limit effort="21.3" lower="0" upper="6.28" velocity="21.3"/>
    </joint>
    <joint name="joint5" type="revolute">
      <origin xyz="0 0 0" rpy="0 0 0"/>
      <parent link="link4"/>
      <child link="link5"/>
        <axis xyz="0 1 0"/>
      <limit effort="21.3" lower="0" upper="6.28" velocity="21.3"/>
    </joint>


     <!-- BASKET JOINTS-->
     <joint name="join_basket_0" type="revolute">
      <origin xyz="0 0 0" rpy="0 0 0"/>
      <parent link="link5"/>
      <child link="basket_wall1"/>
        <axis xyz="0 0 1"/>
      <limit effort="21.3" lower="0" upper="6.28" velocity="21.3"/>
    </joint>

    <joint name="join_basket_1" type="fixed">
      <origin xyz="0 0 0" rpy="0 0 0"/>
      <parent link="basket_wall1"/>
      <child link="basket_wall2"/>
        <axis xyz="0 0 1"/>
      <limit effort="21.3" lower="0" upper="6.28" velocity="21.3"/>
    </joint>
    <joint name="join_basket_2" type="fixed">
      <origin xyz="0 0 0" rpy="0 0 0"/>
      <parent link="basket_wall2"/>
      <child link="basket_wall3"/>
        <axis xyz="0 0 1"/>
      <limit effort="21.3" lower="0" upper="6.28" velocity="21.3"/>
    </joint>
    <joint name="join_basket_3" type="fixed">
      <origin xyz="0 0 0" rpy="0 0 0"/>
      <parent link="basket_wall3"/>
      <child link="basket_wall4"/>
        <axis xyz="0 0 1"/>
      <limit effort="21.3" lower="0" upper="6.28" velocity="21.3"/>
    </joint>
        <joint name="join_basket_4" type="fixed">
      <origin xyz="0 0 0" rpy="0 0 0"/>
      <parent link="basket_wall4"/>
      <child link="basket_wall5"/>
        <axis xyz="0 0 1"/>
      <limit effort="21.3" lower="0" upper="6.28" velocity="21.3"/>
    </joint>
<!--     <joint name="joint4" type="spherical">
      <origin xyz="0 0 0" rpy="0 0 0"/>
      <parent link="link3"/>
      <child link="link4"/>
      <limit effort="100" lower="-100" upper="100" velocity="100"/>
    </joint> -->
</robot>

</xml>